Traceback (most recent call last):
  File "C:\Users\Miguel\anaconda3\Lib\site-packages\jupyter_cache\executors\utils.py", line 58, in single_nb_execution
    executenb(
  File "C:\Users\Miguel\anaconda3\Lib\site-packages\nbclient\client.py", line 1204, in execute
    return NotebookClient(nb=nb, resources=resources, km=km, **kwargs).execute()
           ^^^^^^^^^^^^^^^^^^^^^^^^^^^^^^^^^^^^^^^^^^^^^^^^^^^^^^^^^^^^^^^^^^^^^
  File "C:\Users\Miguel\anaconda3\Lib\site-packages\nbclient\util.py", line 84, in wrapped
    return just_run(coro(*args, **kwargs))
           ^^^^^^^^^^^^^^^^^^^^^^^^^^^^^^^
  File "C:\Users\Miguel\anaconda3\Lib\site-packages\nbclient\util.py", line 62, in just_run
    return loop.run_until_complete(coro)
           ^^^^^^^^^^^^^^^^^^^^^^^^^^^^^
  File "C:\Users\Miguel\anaconda3\Lib\asyncio\base_events.py", line 653, in run_until_complete
    return future.result()
           ^^^^^^^^^^^^^^^
  File "C:\Users\Miguel\anaconda3\Lib\site-packages\nbclient\client.py", line 663, in async_execute
    await self.async_execute_cell(
  File "C:\Users\Miguel\anaconda3\Lib\site-packages\nbclient\client.py", line 965, in async_execute_cell
    await self._check_raise_for_error(cell, cell_index, exec_reply)
  File "C:\Users\Miguel\anaconda3\Lib\site-packages\nbclient\client.py", line 862, in _check_raise_for_error
    raise CellExecutionError.from_cell_and_msg(cell, exec_reply_content)
nbclient.exceptions.CellExecutionError: An error occurred while executing the following cell:
------------------
from sklearn.model_selection import cross_val_score
mse["cv"] = [-np.mean(cross_val_score(linear_model.Lasso(alpha=alpha, max_iter=50000),
                                  X_train, y_train, cv=5, scoring='neg_mean_squared_error'))
          for alpha in alphas]
mse.plot(x="log_alpha", y="cv", c=colors[2], ax=ax)
ax.annotate("5 fold cross-validation", (mse.log_alpha[40], mse.cv[40]), color=colors[2])
ax.get_legend().remove()
ax.set_xlabel(r"$-\log(\alpha)$")
ax.set_ylabel("MSE")
fig
------------------

[1;31m---------------------------------------------------------------------------[0m
[1;31mNameError[0m                                 Traceback (most recent call last)
Cell [1;32mIn[7], line 2[0m
[0;32m      1[0m [38;5;28;01mfrom[39;00m [38;5;21;01msklearn[39;00m[38;5;21;01m.[39;00m[38;5;21;01mmodel_selection[39;00m [38;5;28;01mimport[39;00m cross_val_score
[1;32m----> 2[0m mse[[38;5;124m"[39m[38;5;124mcv[39m[38;5;124m"[39m] [38;5;241m=[39m [[38;5;241m-[39mnp[38;5;241m.[39mmean(cross_val_score(linear_model[38;5;241m.[39mLasso(alpha[38;5;241m=[39malpha, max_iter[38;5;241m=[39m[38;5;241m50000[39m),
[0;32m      3[0m                                   X_train, y_train, cv[38;5;241m=[39m[38;5;241m5[39m, scoring[38;5;241m=[39m[38;5;124m'[39m[38;5;124mneg_mean_squared_error[39m[38;5;124m'[39m))
[0;32m      4[0m           [38;5;28;01mfor[39;00m alpha [38;5;129;01min[39;00m alphas]
[0;32m      5[0m mse[38;5;241m.[39mplot(x[38;5;241m=[39m[38;5;124m"[39m[38;5;124mlog_alpha[39m[38;5;124m"[39m, y[38;5;241m=[39m[38;5;124m"[39m[38;5;124mcv[39m[38;5;124m"[39m, c[38;5;241m=[39mcolors[[38;5;241m2[39m], ax[38;5;241m=[39max)
[0;32m      6[0m ax[38;5;241m.[39mannotate([38;5;124m"[39m[38;5;124m5 fold cross-validation[39m[38;5;124m"[39m, (mse[38;5;241m.[39mlog_alpha[[38;5;241m40[39m], mse[38;5;241m.[39mcv[[38;5;241m40[39m]), color[38;5;241m=[39mcolors[[38;5;241m2[39m])

[1;31mNameError[0m: name 'mse' is not defined
NameError: name 'mse' is not defined

