Traceback (most recent call last):
  File "C:\Users\Miguel\anaconda3\Lib\site-packages\jupyter_cache\executors\utils.py", line 58, in single_nb_execution
    executenb(
  File "C:\Users\Miguel\anaconda3\Lib\site-packages\nbclient\client.py", line 1204, in execute
    return NotebookClient(nb=nb, resources=resources, km=km, **kwargs).execute()
           ^^^^^^^^^^^^^^^^^^^^^^^^^^^^^^^^^^^^^^^^^^^^^^^^^^^^^^^^^^^^^^^^^^^^^
  File "C:\Users\Miguel\anaconda3\Lib\site-packages\nbclient\util.py", line 84, in wrapped
    return just_run(coro(*args, **kwargs))
           ^^^^^^^^^^^^^^^^^^^^^^^^^^^^^^^
  File "C:\Users\Miguel\anaconda3\Lib\site-packages\nbclient\util.py", line 62, in just_run
    return loop.run_until_complete(coro)
           ^^^^^^^^^^^^^^^^^^^^^^^^^^^^^
  File "C:\Users\Miguel\anaconda3\Lib\asyncio\base_events.py", line 653, in run_until_complete
    return future.result()
           ^^^^^^^^^^^^^^^
  File "C:\Users\Miguel\anaconda3\Lib\site-packages\nbclient\client.py", line 663, in async_execute
    await self.async_execute_cell(
  File "C:\Users\Miguel\anaconda3\Lib\site-packages\nbclient\client.py", line 965, in async_execute_cell
    await self._check_raise_for_error(cell, cell_index, exec_reply)
  File "C:\Users\Miguel\anaconda3\Lib\site-packages\nbclient\client.py", line 862, in _check_raise_for_error
    raise CellExecutionError.from_cell_and_msg(cell, exec_reply_content)
nbclient.exceptions.CellExecutionError: An error occurred while executing the following cell:
------------------
lasso_model = linear_model.Lasso()
lasso_model.fit(X, y)

lasso_coefs = pd.Series(dict(zip(list(X), lasso_model.coef_)))
lr_coefs = pd.Series(dict(zip(list(X), lr_model.coef_)))
coefs = pd.DataFrame(dict(lasso=lasso_coefs, linreg=lr_coefs))
coefs
------------------

[1;31m---------------------------------------------------------------------------[0m
[1;31mNameError[0m                                 Traceback (most recent call last)
Cell [1;32mIn[2], line 5[0m
[0;32m      2[0m lasso_model[38;5;241m.[39mfit(X, y)
[0;32m      4[0m lasso_coefs [38;5;241m=[39m pd[38;5;241m.[39mSeries([38;5;28mdict[39m([38;5;28mzip[39m([38;5;28mlist[39m(X), lasso_model[38;5;241m.[39mcoef_)))
[1;32m----> 5[0m lr_coefs [38;5;241m=[39m pd[38;5;241m.[39mSeries([38;5;28mdict[39m([38;5;28mzip[39m([38;5;28mlist[39m(X), lr_model[38;5;241m.[39mcoef_)))
[0;32m      6[0m coefs [38;5;241m=[39m pd[38;5;241m.[39mDataFrame([38;5;28mdict[39m(lasso[38;5;241m=[39mlasso_coefs, linreg[38;5;241m=[39mlr_coefs))
[0;32m      7[0m coefs

[1;31mNameError[0m: name 'lr_model' is not defined
NameError: name 'lr_model' is not defined

